<?xml version="1.0" encoding="UTF-8"?>
<testng-results ignored="0" total="2" passed="1" failed="1" skipped="0">
  <reporter-output>
  </reporter-output>
  <suite started-at="2024-09-22T21:00:54 ICT" name="Default suite" finished-at="2024-09-22T21:01:48 ICT" duration-ms="54119">
    <groups>
    </groups>
    <test started-at="2024-09-22T21:00:54 ICT" name="Default test" finished-at="2024-09-22T21:01:48 ICT" duration-ms="54119">
      <class name="autotest.testcases.LoginTestcases">
        <test-method is-config="true" signature="startPage()[pri:0, instance:autotest.testcases.LoginTestcases@54a7079e]" started-at="2024-09-22T21:00:54 ICT" name="startPage" finished-at="2024-09-22T21:01:12 ICT" duration-ms="18016" status="PASS">
          <reporter-output>
          </reporter-output>
        </test-method> <!-- startPage -->
        <test-method signature="loginFail()[pri:0, instance:autotest.testcases.LoginTestcases@54a7079e]" started-at="2024-09-22T21:01:12 ICT" name="loginFail" finished-at="2024-09-22T21:01:29 ICT" duration-ms="17170" status="PASS">
          <reporter-output>
          </reporter-output>
        </test-method> <!-- loginFail -->
        <test-method signature="loginFail1()[pri:0, instance:autotest.testcases.LoginTestcases@54a7079e]" started-at="2024-09-22T21:01:29 ICT" name="loginFail1" finished-at="2024-09-22T21:01:47 ICT" duration-ms="17820" status="FAIL">
          <exception class="java.lang.AssertionError">
            <full-stacktrace>
              <![CDATA[java.lang.AssertionError
at autotest.testcases.LoginTestcases.loginFail1(LoginTestcases.java:36)
at java.base/jdk.internal.reflect.DirectMethodHandleAccessor.invoke(DirectMethodHandleAccessor.java:103)
at java.base/java.lang.reflect.Method.invoke(Method.java:580)
at org.testng.internal.MethodInvocationHelper.invokeMethod(MethodInvocationHelper.java:133)
at org.testng.internal.TestInvoker.invokeMethod(TestInvoker.java:598)
at org.testng.internal.TestInvoker.invokeTestMethod(TestInvoker.java:173)
at org.testng.internal.MethodRunner.runInSequence(MethodRunner.java:46)
at org.testng.internal.TestInvoker$MethodInvocationAgent.invoke(TestInvoker.java:824)
at org.testng.internal.TestInvoker.invokeTestMethods(TestInvoker.java:146)
at org.testng.internal.TestMethodWorker.invokeTestMethods(TestMethodWorker.java:146)
at org.testng.internal.TestMethodWorker.run(TestMethodWorker.java:128)
at java.base/java.util.ArrayList.forEach(ArrayList.java:1597)
at org.testng.TestRunner.privateRun(TestRunner.java:794)
at org.testng.TestRunner.run(TestRunner.java:596)
at org.testng.SuiteRunner.runTest(SuiteRunner.java:377)
at org.testng.SuiteRunner.runSequentially(SuiteRunner.java:371)
at org.testng.SuiteRunner.privateRun(SuiteRunner.java:332)
at org.testng.SuiteRunner.run(SuiteRunner.java:276)
at org.testng.SuiteRunnerWorker.runSuite(SuiteRunnerWorker.java:53)
at org.testng.SuiteRunnerWorker.run(SuiteRunnerWorker.java:96)
at org.testng.TestNG.runSuitesSequentially(TestNG.java:1212)
at org.testng.TestNG.runSuitesLocally(TestNG.java:1134)
at org.testng.TestNG.runSuites(TestNG.java:1063)
at org.testng.TestNG.run(TestNG.java:1031)
at org.testng.remote.AbstractRemoteTestNG.run(AbstractRemoteTestNG.java:115)
at org.testng.remote.RemoteTestNG.initAndRun(RemoteTestNG.java:293)
at org.testng.remote.RemoteTestNG.main(RemoteTestNG.java:91)
]]>
            </full-stacktrace>
          </exception> <!-- java.lang.AssertionError -->
          <reporter-output>
          </reporter-output>
        </test-method> <!-- loginFail1 -->
        <test-method is-config="true" signature="closePage()[pri:0, instance:autotest.testcases.LoginTestcases@54a7079e]" started-at="2024-09-22T21:01:47 ICT" name="closePage" finished-at="2024-09-22T21:01:48 ICT" duration-ms="972" status="PASS">
          <reporter-output>
          </reporter-output>
        </test-method> <!-- closePage -->
      </class> <!-- autotest.testcases.LoginTestcases -->
    </test> <!-- Default test -->
  </suite> <!-- Default suite -->
</testng-results>
